2024-09-11 10:40:01,487 ERROR scheduler Exception in Enqueue Events for Site saralrat
Traceback (most recent call last):
  File "/home/ecosoft/frappe-bench/apps/frappe/frappe/utils/scheduler.py", line 106, in enqueue_events_for_site
    if is_scheduler_inactive():
  File "/home/ecosoft/frappe-bench/apps/frappe/frappe/utils/scheduler.py", line 150, in is_scheduler_inactive
    if is_scheduler_disabled(verbose=verbose):
  File "/home/ecosoft/frappe-bench/apps/frappe/frappe/utils/scheduler.py", line 163, in is_scheduler_disabled
    frappe.db.get_single_value("System Settings", "enable_scheduler")
  File "/home/ecosoft/frappe-bench/apps/frappe/frappe/database/database.py", line 846, in get_single_value
    ).run()
  File "/home/ecosoft/frappe-bench/apps/frappe/frappe/query_builder/utils.py", line 84, in execute_query
    result = frappe.db.sql(query, params, *args, **kwargs)  # nosemgrep
  File "/home/ecosoft/frappe-bench/apps/frappe/frappe/database/database.py", line 213, in sql
    self.connect()
  File "/home/ecosoft/frappe-bench/apps/frappe/frappe/database/database.py", line 118, in connect
    self._conn: "MariadbConnection" | "PostgresConnection" = self.get_connection()
  File "/home/ecosoft/frappe-bench/apps/frappe/frappe/database/mariadb/database.py", line 107, in get_connection
    conn = self._get_connection()
  File "/home/ecosoft/frappe-bench/apps/frappe/frappe/database/mariadb/database.py", line 113, in _get_connection
    return self.create_connection()
  File "/home/ecosoft/frappe-bench/apps/frappe/frappe/database/mariadb/database.py", line 116, in create_connection
    return pymysql.connect(**self.get_connection_settings())
  File "/home/ecosoft/frappe-bench/env/lib/python3.10/site-packages/pymysql/connections.py", line 361, in __init__
    self.connect()
  File "/home/ecosoft/frappe-bench/env/lib/python3.10/site-packages/pymysql/connections.py", line 669, in connect
    self._request_authentication()
  File "/home/ecosoft/frappe-bench/env/lib/python3.10/site-packages/pymysql/connections.py", line 957, in _request_authentication
    auth_packet = self._read_packet()
  File "/home/ecosoft/frappe-bench/env/lib/python3.10/site-packages/pymysql/connections.py", line 775, in _read_packet
    packet.raise_for_error()
  File "/home/ecosoft/frappe-bench/env/lib/python3.10/site-packages/pymysql/protocol.py", line 219, in raise_for_error
    err.raise_mysql_exception(self._data)
  File "/home/ecosoft/frappe-bench/env/lib/python3.10/site-packages/pymysql/err.py", line 150, in raise_mysql_exception
    raise errorclass(errno, errval)
pymysql.err.OperationalError: (1045, "Access denied for user '_ddce7bd064efd9b5'@'localhost' (using password: YES)")
2024-09-13 13:04:01,334 ERROR scheduler Skipped queueing hrms.hr.doctype.shift_type.shift_type.process_auto_attendance_for_all_shifts because it was found in queue for saralrat
2024-09-13 13:04:01,355 ERROR scheduler Skipped queueing erpnext.stock.doctype.repost_item_valuation.repost_item_valuation.repost_entries because it was found in queue for saralrat
2024-09-13 13:04:01,376 ERROR scheduler Skipped queueing hrms.hr.doctype.shift_assignment_schedule.shift_assignment_schedule.process_auto_shift_creation because it was found in queue for saralrat
